<?xml version="1.0"?>
<robot xmlns:xacro="http://www.ros.org/wiki/xacro">

  <!-- 车轮基本属性 -->
  <xacro:property name="wheel_radius" value="0.06" />
  <xacro:property name="wheel_height" value="0.03" />
  <xacro:property name="wheel_mass"   value="0.5" />

  <!-- 车轮与底盘中心的偏移系数（相对于 base_radius） -->
  <xacro:property name="base_x_origin_to_wheel_origin" value="0.25" />
  <xacro:property name="base_y_origin_to_wheel_origin" value="0.30" />
  <xacro:property name="base_z_origin_to_wheel_origin" value="0.0" />

  <!-- 惯性矩阵宏 -->
  <xacro:macro name="cylinder_inertia" params="m r h">
    <inertia ixx="${m*(3*r*r+h*h)/12}" ixy="0.0" ixz="0.0"
             iyy="${m*(3*r*r+h*h)/12}" iyz="0.0"
             izz="${m*r*r/2}" />
  </xacro:macro>

  <!-- 车轮宏：fb 为前/后（未使用），lr 为左/右，parent 为父 link，translateX/Y 为方向系数，flipY 用于翻转 -->
  <xacro:macro name="wheel" params="fb lr parent translateX translateY flipY">
    <link name="${fb}_${lr}_wheel">
      <inertial>
        <mass value="${wheel_mass}" />
        <origin xyz="0 0 0" />
        <xacro:cylinder_inertia m="${wheel_mass}" r="${wheel_radius}" h="${wheel_height}" />
      </inertial>
      <visual>
        <origin xyz="0 0 0" rpy="${flipY*M_PI/2} 0 0" />
        <geometry>
          <cylinder radius="${wheel_radius}" length="${wheel_height}" />
        </geometry>
        <material name="Gray" />
      </visual>
      <collision>
        <origin xyz="0 0 0" rpy="${flipY*M_PI/2} 0 0" />
        <geometry>
          <cylinder radius="${wheel_radius}" length="${wheel_height}" />
        </geometry>
      </collision>
    </link>

    <gazebo reference="${fb}_${lr}_wheel">
      <mu1 value="1.0"/>
      <mu2 value="1.0"/>
      <kp value="10000000.0" />
      <kd value="1.0" />
      <fdir1 value="1 0 0"/>
      <material>Gazebo/Grey</material>
      <turnGravityOff>false</turnGravityOff>
    </gazebo>

    <joint name="${fb}_${lr}_wheel_joint" type="continuous">
      <parent link="${parent}"/>
      <child link="${fb}_${lr}_wheel"/>
      <origin xyz="${translateX * base_x_origin_to_wheel_origin} ${translateY * base_y_origin_to_wheel_origin} ${base_z_origin_to_wheel_origin}" rpy="0 0 0" />
      <axis xyz="0 1 0" />
      <limit effort="100" velocity="100"/>
      <joint_properties damping="0.0" friction="0.0"/>
    </joint>

    <!-- 传动（必需） -->
    <transmission name="${fb}_${lr}_wheel_joint_trans">
      <type>transmission_interface/SimpleTransmission</type>
      <joint name="${fb}_${lr}_wheel_joint" />
      <actuator name="${fb}_${lr}_wheel_joint_motor">
        <hardwareInterface>EffortJointInterface</hardwareInterface>
        <mechanicalReduction>1</mechanicalReduction>
      </actuator>
    </transmission>
  </xacro:macro>

</robot>
